Workbook

Sheet Offer Calculator
C3: Wholesale vs. Installment Offer Calculator
C5: KEY: | E5: Orange Highligted Field | H5: = | I5: Editable Field
E6: Grey Highlighted Field | H6: = | I6: Variable Cost Only Known After Getting An Offer
A10: USER INPUTS | G10: WHOLESALE OFFER
A11: (Using ARV)
G12: =C13 -> 200000 | I12: ARV
A13: After Repaired Value ("ARV") | C13: 200000 | F13: x | G13: =C41 -> 0.7 | I13: % of ARV for Wholesale Deals
F14: = | G14: =G12*G13 -> 140000 | I14: All-In Amount
A15: Estimated Repairs (click link below for an estimator tool) | C15: 30000 | F15: - | G15: =C15 -> 30000 | I15: Estimated Repairs
A16: http://repairs.jvwithcashflowsociety.com/ | F16: - | G16: =IF(C26="Yes",C18,0) -> 0 | I16: Negative Appraisal Factors
F17: + | G17: =IF(C26="Yes",C23,0) -> 0 | I17: Positive Appraisal Factors
A18: Amount To SUBTRACT For Negative Appraisal Factors | C18: 0 | F18: = | G18: =G14-G15-G16+G17 -> 110000 | I18: Sales Price to Another Investor (Assignment Price)
A19: (NOTE: This could be anything that would change the value of the property other than repairs; such as a weird feature of the house, or the property backs up to a commercial property, four lane road/highway, near railroad tracks / water tower / overhead high-voltage power lines, functional obsolescence, etc.) | F19: - | G19: =C53 -> 15000 | I19: Minimum Acceptable Profit
F20: = | G20: =G18-G19 -> 95000 | I20: Wholesale Max. Allowable Offer ("MAO") + Non-Monetary Item
G21: =G20*95% -> 90250 | I21: 3rd Offer - 95% of Wholesale MAO
G22: =G20*85% -> 80750 | I22: 2nd Offer - 85% of Wholesale MAO
A23: Amount To ADD For Positive Appraisal Factors | G23: =G20*65% -> 61750 | I23: 1st Offer - 65% of Wholesale MAO
A24: (NOTE: Such as this house has 4 bedrooms, but all the comps have 3) | G24: (The numbers above come from a technique called the "Ackerman Method of Bargaining" as taught in "Never Split The Difference" by Chris Voss. Click here for key takeaways.)
A26: Do you want to take Appraisal Factors into account for your Wholesale offer? | C26: No
G27: =G20/G12 -> 0.475 | H27: = | I27: Wholesale MAO Purchase Price % of ARV
G28: =1-G27 -> 0.525 | H28: = | I28: Retail Gap % Before Repairs Factored In
A29: "As-Is Value" (=ARV - Est. Repairs - Appraisal Factors) | C29: =C13-C15-C18+C23 -> 170000 | G29: =G12-G15-G20 -> 75000 | H29: = | I29: Retail Gap Gross Profit Potential (ARV - Repairs - MAO)
A31: Recommended Discount To Sell Fast On The M.L.S. | C31: 10000
A32: (NOTE: We recommend listing it for 90% of the "As-Is Value," or $20,000, whichever is less.) | F32: REMEMBER: We can offer 3 things to sellers: 1) Speed; 2) Convenience; or 3) Price. But they can only pick 2 out of those 3. If they want Speed and Convenience, then you'll need to revert back to a Wholesale Offer. If they want Speed and Price, then we can only buy it Subject-To the existing mortgage staying in place / with Owner Financing if owned free and clear. Most sellers that opt for doing an Installment deal are looking for Price and Convenience.
A35: Discount To Sell Fast On The M.L.S. | C35: 10000
A37: Do you want to factor the Discount into the List Price? | C37: Yes
G38: Installment OFFER
A39: Price To List The Property On The M.L.S. | C39: =IF(C37="No",C29,(C29-C35)) -> 160000
G40: =C13 -> 200000 | I40: ARV
A41: % of ARV that we can sell this as a Wholesale Deal | C41: 0.7 | F41: - | G41: =C15 -> 30000 | I41: Estimated Repairs
A42: (NOTE: Depends on the market. Default = 65%; Max. % = 80%) | F42: - | G42: =C18 -> 0 | I42: Negative Appraisal Factors
F43: + | G43: =C23 | I43: Positive Appraisal Factors
A44: Installment Closing Fees & Out Of Pocket Costs | C44: =SUM('Closing Fees & Out Of Pocket Co'!C36) -> 18400 | F44: - | G44: =IF(C37="Yes",C35,0) -> 10000 | I44: Discount To Sell Fast
A45: (NOTE: See "Closing Fees & Out Of Pocket Costs" tab for a detailed breakdown) | F45: = | G45: =G40-G41-G42+G43-G44 -> 160000 | I45: List Price on the M.L.S.
F46: + | G46: =C62 -> 0 | I46: Amount Offered by End-Buyer Over Asking Price
F47: = | G47: =G45+G46 -> 160000 | I47: Final Sales Price to End-Buyer
A48: Suggested Minimum Profit (FOR REFERENCE ONLY) | C48: 25000 | F48: - | G48: =C44 -> 18400 | I48: Closing Fees & Out Of Pocket Costs
A49: (NOTE: Suggested Minimum Profit on a Installment is the greater of $25,000 or 10% of the Sales Price To Another Investor on a Wholesale Offer [i.e. Assignment Price]. Always shoot for at least 1.5x of that amount to leave room for negotiations.) | F49: = | G49: =G47-G48 -> 141600 | I49: Gross Sales Price After Closing Fees & Out Of Pocket Costs
F50: - | G50: =C53 -> 15000 | I50: Minimum Acceptable Profit
F51: + | G51: =C65 -> 0 | I51: Amount To Split With Seller If Sold Over Asking Price
...

Sheet Closing Fees & Out Of Pocket Co
A1: Installment Closing Costs & Concessions | F1: KEY: | G1: Gray Highlighted Field | I1: = Do not change, if you can avoid it
G2: Orange Highligted Field | I2: = Editable Field
A3: Fees Payable At Closing
A4: Using a Flat Fee Listing Service or Full Service Realtor? | C4: Full Service
A5: Flat Fee Listing Service Fee | C5: 500 | D5: % | F5: Default Settings
A6: Listing Agent's Commission | C6: =IF(C4="Flat Fee",C5,('Offer Calculator'!G47*D6)) -> 3200 | D6: 0.02 | F6: 2.00% - 3.00% of Price To List As-Is. We usually pay Listing Agents 2.5%
A7: Buyer's Agent's Commission | C7: ='Offer Calculator'!G47*D7 -> 3200 | D7: 0.02 | F7: 2.00% - 3.00% of Price To List As-Is. We like to pay Buyers Agents 3.5%
A8: Title & Escrow Fees | C8: ='Offer Calculator'!G47*D8 -> 1600 | D8: 0.01 | F8: 1.00% - 2.00% of Price To List As-Is.
A9: State / County / City Transfer Taxes | C9: ='Offer Calculator'!G47*D9 -> 0 | D9: 0 | F9: Usually 0.10% to 1.00% of Price To List As-Is. But check with your escrow agent or Google how much transfer taxes are in your area.
A10: Loan Concessions / Repair Credits to Buyer | C10: ='Offer Calculator'!G47*D10 -> 400 | D10: 0.0025 | F10: 1.00% - 3.00% of Price To List As-Is.
A11: Buyer's Appraisal Fee (paid by Seller) | C11: 0 | F11: If required, $500.
A12: Home Warranty Fee for Buyer | C12: 650 | F12: $550 - $750
A13: HOA Resale Certificate Fee | C13: 500 | F13: 500
A14: HOA Transfer Fee | C14: 350 | F14: 350
A15: HOA Capital Improvement / Reserve Fees | C15: 0 | F15: $0 for SFR houses. But check with the HOA or your escrow agent. Usually this only applies to Condos and Townhouses.
A16: New Survey | C16: 650 | F16: $450 - $750. Only if the Seller doesn't have an existing one on file.
A17: Attorney Fees for Seller (attorney closing states only) | C17: 0 | F17: $1,000 to $3,000 if working in an attorney-closing state. List of Attorney vs. Title States.
A18: Private Lending Costs To Borrow Money For Repairs | C18: 0 | F18: $0 - But if you're using a service like Revive or Curbio, it'll cost roughly 15% of the loan amount as a "convenience fee." With Compass Concierge, it's $0.
A19: Other | C19: 0 | F19: 0
A20: Total Fees Payable At Closing = | C20: =SUM(C6:C19) -> 10550
A22: Out Of Pocket (O.O.P.) Costs Payable Prior To Closing | F22: Default Settings
A23: Are we willing to pay for Repairs prior to closing? | C23: Yes
A24: Max. Amount To Pay For Minor Repairs Prior To Listing | C24: =IF(C23="No",0,(IF(('Offer Calculator'!C15*10%)<(5000),('Offer Calculator'!C15*10%),(5000)))) -> 3000 | F24: We're only willing to put in up to 10% of the Repair Budget prior to closing, with a maximum amount of up to $5,000. **Equation in case it gets deleted ----------------------------------------------> | P24: =IF(C23="No",0,(IF(('Offer Calculator'!C15*10%)<(5000),('Offer Calculator'!C15*10%),(5000))))
A25: Earnest Money Deposit | C25: 0 | F25: Default = 0.5%; Min. $100, but up to 1.00% of the Purchase Price. Reimbursable once you cancel the A-B contract with the seller and put them into the A-C contract with the end-buyer.
A26: Due Diligence Inspection Fees | C26: 1000 | F26: $500 to $2,000. Depends on amount of issues at the property. Will cost more if there's a pool, septic system, and/or well on the property.
A27: Make-Ready Cleaning Fees | C27: 750 | F27: $500 - $1,000
A28: Professional Photography for Marketing | C28: 350 | F28: 350
A29: Matterport 3D Walk-Through | C29: 250 | F29: 250
A30: Professional Staging | C30: 2500 | F30: $1,500 - $3,500
A31: Other - 1 | C31: 0 | F31: 0
A32: Other - 2 | C32: 0 | F32: 0
A33: Other - 3 | C33: 0 | F33: 0
A34: Total Out Of Pocket Costs Prior To Closing = | C34: =SUM(C24:C33) -> 7850
A36: TOTAL OUT OF POCKET COSTS & FEES PAYABLE AT CLOSING | B36: = | C36: =SUM(C20,C34) -> 18400

Sheet No Comps, but have Rents Calcul
A2: USER INPUTS | G2: KEY: | I2: Orange Highligted Field | J2: = | K2: Editable Field
A3: (Using Expected Rent and Cap Rate) | I3: Grey Highlighted Field | J3: = | K3: Variable Cost Only Known After Getting An Offer
A7: After Repaired Rent Rate Per Month | C7: 2000 | G7: WHOLESALE OFFER
A9: Desired Cap Rate | C9: 0.0525 | G9: =C18 -> 274290 | I9: ARV
A10: (We usually shoot for a min. 5.00-7.00% Cap Rate in today's market. Check with your local realtor to confirm cap rates.) | F10: x | G10: =C46 -> 0.7 | I10: % of ARV for Wholesale Deals
F11: = | G11: =G9*G10 -> 192003 | I11: All-In Amount
F12: - | G12: =C20 -> 17500 | I12: Estimated Repairs
A13: Estimated Expense Ratio as a Rental | C13: 0.4 | F13: - | G13: =IF(C32="Yes",C23,0) -> 10000 | I13: Negative Appraisal Factors
A14: (We usually shoot for a max. 40.00% Expense Ratio, meaning if it would rent for $1,000/mo. then $400 of that would go toward expenses other than PITI / Debt Service) | F14: + | G14: =IF(C32="Yes",C29,0) -> 5000 | I14: Positive Appraisal Factors
F15: = | G15: =G11-G12-G13+G14 -> 169503 | I15: Sales Price to Another Investor (Assignment Price)
F16: - | G16: =C58 -> 25000 | I16: Minimum Acceptable Profit
F17: = | G17: =G15-G16 -> 144503 | I17: Wholesale Max. Allowable Offer ("MAO") + Non-Monetary Item
A18: Assumed After Repaired Value ("ARV") | C18: =ROUND(((C7*12)*(1-C13))/C9,-1) -> 274290 | G18: =G17*95% -> 137277.85 | I18: 3rd Offer - 95% of Installment MAO
G19: =G17*85% -> 122827.55 | I19: 2nd Offer - 85% of Novaiton MAO
A20: Estimated Repairs (click link below for an estimator tool) | C20: 17500 | G20: =G17*65% -> 93926.95 | I20: 1st Offer - 65% of Installment MAO
A21: http://repairs.jvwithcashflowsociety.com/ | G21: (The numbers above come from a technique called the "Ackerman Method of Bargaining" as taught in "Never Split The Difference" by Chris Voss. Click here for key takeaways.)
A23: Amount To SUBTRACT For Negative Appraisal Factors | C23: 10000
A24: (NOTE: This could be anything that would change the value of the property other than repairs; such as a weird feature of the house, or the property backs up to a commercial property, four lane road/highway, near railroad tracks / water tower / overhead high-voltage power lines, functional obsolescence, etc.) | G24: =G17/G9 -> 0.52682562 | H24: = | I24: Wholesale MAO Purchase Price % of ARV
G25: =1-G24 -> 0.47317438 | H25: = | I25: Retail Gap % Before Repairs Factored In
G26: =G9-G12-G17 -> 112287 | H26: = | I26: Retail Gap Gross Profit Potential (ARV - Repairs - MAO)
A29: Amount To ADD For Positive Appraisal Factors | C29: 5000
A30: (NOTE: Such as this house has 4 bedrooms, but all the comps have 3) | F30: REMEMBER: We can offer 3 things to sellers: 1) Speed; 2) Convenience; or 3) Price. But they can only pick 2 out of those 3. If they want Speed and Convenience, then you'll need to revert back to a Wholesale Offer. If they want Speed and Price, then we can only buy it Subject-To the existing mortgage staying in place / with Owner Financing if owned free and clear. Most sellers that opt for doing a Installment deal are looking for Price and Convenience.
A32: Do you want to take Appraisal Factors into account for your Wholesale offer? | C32: Yes
A35: "As-Is Value" (=ARV - Est. Repairs - Appraisal Factors) | C35: =C18-C20-C23+C29 -> 251790
G36: Installment OFFER
A37: Recommended Discount To Sell Fast On The M.L.S. | C37: =IF((C35*5%)>20000,20000,(C35*5%)) -> 12589.5
A38: (NOTE: We recommend listing it for 95% of the "As-Is Value," or $20,000, whichever is less.) | G38: =C18 -> 274290 | I38: ARV
F39: - | G39: =C20 -> 17500 | I39: Estimated Repairs
A40: Discount To Sell Fast On The M.L.S. | C40: 11890 | F40: - | G40: =C23 -> 10000 | I40: Negative Appraisal Factors
F41: + | G41: =C29 -> 5000 | I41: Positive Appraisal Factors
A42: Do you want to factor the Discount into the List Price? | C42: Yes | F42: - | G42: =IF(C42="Yes",C40,0) -> 11890 | I42: Discount To Sell Fast
F43: = | G43: =G38-G39-G40+G41-G42 -> 239900 | I43: List Price on the M.L.S.
A44: Price To List The Property On The M.L.S. | C44: =IF(C42="No",C35,(C35-C40)) -> 239900 | F44: + | G44: =C66 -> 0 | I44: Amount Offered by End-Buyer Over Asking Price
F45: = | G45: =G43+G44 -> 239900 | I45: Final Sales Price to End-Buyer
A46: % of ARV that we can sell this as a Wholesale Deal | C46: 0.7 | F46: - | G46: =C49 -> 37139 | I46: Out Of Pocket Costs & Fees Payable At Closing
A47: (NOTE: Depends on the market. Default = 65%; Max. % = 80%) | F47: = | G47: =G45-G46 -> 202761 | I47: Gross Sales Price After O.O.P Costs & Fees
F48: - | G48: =C58 -> 25000 | I48: Minimum Acceptable Profit
A49: Installment Closing Fees & Out Of Pocket Costs | C49: =Sheet7!C36 -> 37139 | F49: + | G49: =C69 -> 0 | I49: Amount To Split With Seller If Sold Over Asking Price
A50: (NOTE: See "Closing Fees & Out Of Pocket Costs" tab for a detailed breakdown) | F50: = | G50: =G47-G48+G49 -> 177761 | I50: Installment Max. Allowable Offer ("MAO")
G51: =G50*95% -> 168872.95 | I51: 3rd Offer - 95% of Installment MAO
...

Sheet Sheet7
A1: Installment Closing Costs & Concessions | F1: KEY: | G1: Gray Highlighted Field | I1: = Do not change, if you can avoid it
G2: Orange Highligted Field | I2: = Editable Field
A3: Fees Payable At Closing
A4: Using a Flat Fee Listing Service or Full Service Realtor? | C4: Full Service
A5: Flat Fee Listing Service Fee | C5: 500 | D5: % | F5: Default Settings
A6: Listing Agent's Commission | C6: =IF(C4="Flat Fee",C5,('No Comps, but have Rents Calcul'!C44*D6)) -> 5997.5 | D6: 0.025 | F6: 2.00% - 3.00% of Price To List As-Is. We usually pay Listing Agents 2.5%
A7: Buyer's Agent's Commission | C7: ='No Comps, but have Rents Calcul'!C44*D7 -> 8396.5 | D7: 0.035 | F7: 2.00% - 3.00% of Price To List As-Is. We like to pay Buyers Agents 3.5%
A8: Title & Escrow Fees | C8: ='No Comps, but have Rents Calcul'!C44*D8 -> 3598.5 | D8: 0.015 | F8: 1.00% - 2.00% of Price To List As-Is.
A9: State / County / City Transfer Taxes | C9: ='No Comps, but have Rents Calcul'!C44*D9 -> 0 | D9: 0 | F9: Usually 0.10% to 1.00% of Price To List As-Is. But check with your escrow agent or Google how much transfer taxes are in your area.
A10: Loan Concessions / Repair Credits to Buyer | C10: ='No Comps, but have Rents Calcul'!C44*D10 -> 7197 | D10: 0.03 | F10: 1.00% - 3.00% of Price To List As-Is.
A11: Buyer's Appraisal Fee (paid by Seller) | C11: 0 | F11: If required, $500.
A12: Home Warranty Fee for Buyer | C12: 650 | F12: $550 - $750
A13: HOA Resale Certificate Fee | C13: 500 | F13: 500
A14: HOA Transfer Fee | C14: 350 | F14: 350
A15: HOA Capital Improvement / Reserve Fees | C15: 0 | F15: $0 for SFR houses. But check with the HOA or your escrow agent. Usually this only applies to Condos and Townhouses.
A16: New Survey | C16: 650 | F16: $450 - $750. Only if the Seller doesn't have an existing one on file.
A17: Attorney Fees for Seller (attorney closing states only) | C17: 2000 | F17: $1,000 to $3,000 if working in an attorney-closing state. List of Attorney vs. Title States.
A18: Private Lending Costs To Borrow Money For Repairs | C18: 0 | F18: $0 - But if you're using a service like Revive or Curbio, it'll cost roughly 15% of the loan amount as a "convenience fee." With Compass Concierge, it's $0.
A19: Other | C19: 0 | F19: 0
A20: Total Fees Payable At Closing = | C20: =SUM(C6:C19) -> 29339.5
A22: Out Of Pocket (O.O.P.) Costs Payable Prior To Closing | F22: Default Settings
A23: Are we willing to pay for Repairs prior to closing? | C23: Yes
A24: Max. Amount To Pay For Minor Repairs Prior To Listing | C24: =IF(C23="No",0,(IF(('No Comps, but have Rents Calcul'!C20*10%)<(5000),('No Comps, but have Rents Calcul'!C20*10%),(5000)))) -> 1750 | F24: We're only willing to put in up to 10% of the Repair Budget prior to closing, with a maximum amount of up to $5,000. **Equation in case it gets deleted ----------------------------------------------> | P24: =IF(C23="No",0,(IF(('No Comps, but have Rents? Calculate Offer This Way'!C9*10%)<(5000),('No Comps, but have Rents? Calculate Offer This Way'!C9*10%),(5000))))
A25: Earnest Money Deposit | C25: ='No Comps, but have Rents Calcul'!G45*0.5% -> 1199.5 | F25: Default = 0.5%; Min. $100, but up to 1.00% of the Purchase Price. Reimbursable once you cancel the A-B contract with the seller and put them into the A-C contract with the end-buyer.
A26: Due Diligence Inspection Fees | C26: 1000 | F26: $500 to $2,000. Depends on amount of issues at the property. Will cost more if there's a pool, septic system, and/or well on the property.
A27: Make-Ready Cleaning Fees | C27: 750 | F27: $500 - $1,000
A28: Professional Photography for Marketing | C28: 350 | F28: 350
A29: Matterport 3D Walk-Through | C29: 250 | F29: 250
A30: Professional Staging | C30: 2500 | F30: $1,500 - $3,500
A31: Other - 1 | C31: 0 | F31: 0
A32: Other - 2 | C32: 0 | F32: 0
A33: Other - 3 | C33: 0 | F33: 0
A34: Total Out Of Pocket Costs Prior To Closing = | C34: =SUM(C24:C33) -> 7799.5
A36: TOTAL OUT OF POCKET COSTS & FEES PAYABLE AT CLOSING | B36: = | C36: =SUM(C20,C34) -> 37139
